Traceback (most recent call last):
  File "WebsockerServer.py", line 237, in <module>
    server.start()
  File "WebsockerServer.py", line 229, in start
    asyncio.get_event_loop().run_until_complete(websockets.serve(self.msg_handler,'0.0.0.0',self.port))
  File "/usr/lib/python3.8/asyncio/base_events.py", line 616, in run_until_complete
    return future.result()
  File "/usr/lib/python3.8/asyncio/tasks.py", line 695, in _wrap_awaitable
    return (yield from awaitable.__await__())
  File "/usr/local/lib/python3.8/dist-packages/websockets/legacy/server.py", line 1086, in __await_impl__
    server = await self._create_server()
  File "/usr/lib/python3.8/asyncio/base_events.py", line 1463, in create_server
    raise OSError(err.errno, 'error while attempting '
OSError: [Errno 98] error while attempting to bind on address ('0.0.0.0', 8081): address already in use
connection handler failed
Traceback (most recent call last):
  File "/usr/local/lib/python3.8/dist-packages/websockets/legacy/protocol.py", line 944, in transfer_data
    message = await self.read_message()
  File "/usr/local/lib/python3.8/dist-packages/websockets/legacy/protocol.py", line 1013, in read_message
    frame = await self.read_data_frame(max_size=self.max_size)
  File "/usr/local/lib/python3.8/dist-packages/websockets/legacy/protocol.py", line 1088, in read_data_frame
    frame = await self.read_frame(max_size)
  File "/usr/local/lib/python3.8/dist-packages/websockets/legacy/protocol.py", line 1143, in read_frame
    frame = await Frame.read(
  File "/usr/local/lib/python3.8/dist-packages/websockets/legacy/framing.py", line 70, in read
    data = await reader(2)
  File "/usr/lib/python3.8/asyncio/streams.py", line 723, in readexactly
    await self._wait_for_data('readexactly')
  File "/usr/lib/python3.8/asyncio/streams.py", line 517, in _wait_for_data
    await self._waiter
asyncio.exceptions.CancelledError

The above exception was the direct cause of the following exception:

Traceback (most recent call last):
  File "/usr/local/lib/python3.8/dist-packages/websockets/legacy/server.py", line 232, in handler
    await self.ws_handler(self)
  File "/usr/local/lib/python3.8/dist-packages/websockets/legacy/server.py", line 1144, in _ws_handler
    return await cast(
  File "WebsockerServer.py", line 73, in msg_handler
    async for message in websocket:
  File "/usr/local/lib/python3.8/dist-packages/websockets/legacy/protocol.py", line 481, in __aiter__
    yield await self.recv()
  File "/usr/local/lib/python3.8/dist-packages/websockets/legacy/protocol.py", line 552, in recv
    await self.ensure_open()
  File "/usr/local/lib/python3.8/dist-packages/websockets/legacy/protocol.py", line 929, in ensure_open
    raise self.connection_closed_exc()
websockets.exceptions.ConnectionClosedError: sent 1011 (unexpected error) keepalive ping timeout; no close frame received
connection handler failed
Traceback (most recent call last):
  File "/usr/local/lib/python3.8/dist-packages/websockets/legacy/server.py", line 232, in handler
    await self.ws_handler(self)
  File "/usr/local/lib/python3.8/dist-packages/websockets/legacy/server.py", line 1144, in _ws_handler
    return await cast(
  File "WebsockerServer.py", line 96, in msg_handler
    self.stop_grid(js_data['id'])
  File "WebsockerServer.py", line 162, in stop_grid
    del self.grid_dic[f'{id}']
KeyError: '0cfcaa880c6041548d05afd644af570f'
connection handler failed
Traceback (most recent call last):
  File "/usr/local/lib/python3.8/dist-packages/websockets/legacy/server.py", line 232, in handler
    await self.ws_handler(self)
  File "/usr/local/lib/python3.8/dist-packages/websockets/legacy/server.py", line 1144, in _ws_handler
    return await cast(
  File "WebsockerServer.py", line 96, in msg_handler
    self.stop_grid(js_data['id'])
  File "WebsockerServer.py", line 162, in stop_grid
    del self.grid_dic[f'{id}']
KeyError: '0cfcaa880c6041548d05afd644af570f'
connection handler failed
Traceback (most recent call last):
  File "/usr/local/lib/python3.8/dist-packages/websockets/legacy/server.py", line 232, in handler
    await self.ws_handler(self)
  File "/usr/local/lib/python3.8/dist-packages/websockets/legacy/server.py", line 1144, in _ws_handler
    return await cast(
  File "WebsockerServer.py", line 96, in msg_handler
    self.stop_grid(js_data['id'])
  File "WebsockerServer.py", line 162, in stop_grid
    del self.grid_dic[f'{id}']
KeyError: '0cfcaa880c6041548d05afd644af570f'
connection handler failed
Traceback (most recent call last):
  File "/usr/local/lib/python3.8/dist-packages/websockets/legacy/protocol.py", line 944, in transfer_data
    message = await self.read_message()
  File "/usr/local/lib/python3.8/dist-packages/websockets/legacy/protocol.py", line 1013, in read_message
    frame = await self.read_data_frame(max_size=self.max_size)
  File "/usr/local/lib/python3.8/dist-packages/websockets/legacy/protocol.py", line 1088, in read_data_frame
    frame = await self.read_frame(max_size)
  File "/usr/local/lib/python3.8/dist-packages/websockets/legacy/protocol.py", line 1143, in read_frame
    frame = await Frame.read(
  File "/usr/local/lib/python3.8/dist-packages/websockets/legacy/framing.py", line 70, in read
    data = await reader(2)
  File "/usr/lib/python3.8/asyncio/streams.py", line 723, in readexactly
    await self._wait_for_data('readexactly')
  File "/usr/lib/python3.8/asyncio/streams.py", line 517, in _wait_for_data
    await self._waiter
asyncio.exceptions.CancelledError

The above exception was the direct cause of the following exception:

Traceback (most recent call last):
  File "/usr/local/lib/python3.8/dist-packages/websockets/legacy/server.py", line 232, in handler
    await self.ws_handler(self)
  File "/usr/local/lib/python3.8/dist-packages/websockets/legacy/server.py", line 1144, in _ws_handler
    return await cast(
  File "WebsockerServer.py", line 73, in msg_handler
    async for message in websocket:
  File "/usr/local/lib/python3.8/dist-packages/websockets/legacy/protocol.py", line 481, in __aiter__
    yield await self.recv()
  File "/usr/local/lib/python3.8/dist-packages/websockets/legacy/protocol.py", line 552, in recv
    await self.ensure_open()
  File "/usr/local/lib/python3.8/dist-packages/websockets/legacy/protocol.py", line 929, in ensure_open
    raise self.connection_closed_exc()
websockets.exceptions.ConnectionClosedError: sent 1011 (unexpected error) keepalive ping timeout; no close frame received
